Коротка відповідь: **ні, вони не рівні**:

Різниця полягає в тому, що якщо помилка відбувається в `f1`, тоді її обробляє `.catch` тут:

```js run
promise
  .then(f1)
  .catch(f2);
```

...Але не тут:

```js run
promise
  .then(f1, f2);
```

Це тому, що помилка передається по ланцюжку, а в другому фрагменті коду немає ланцюжка нижче `f1`.

Іншими словами, `.then` передає результати/помилки наступному `.then/catch`. Отже, у першому прикладі нижче є `catch`, а в другому його немає, тому помилка не оброблена.
